Traceback (most recent call last):
  File "<pyshell#16>", line 2, in <module>
Exception: To jest komunikat bledu.
